Workbook

Sheet Dados_P1_FSP_2026_Ciro_V3_Hibri
A1: ABA 1: ARGENTINA (Série Histórica)
A2: Ano | B2: Gasto Público (% PIB) | C2: Déficit Fiscal (% PIB) | D2: Inflação (%) | E2: PIB Real (var. %) | F2: Dívida Públ. (% PIB) | G2: Governo
A3: 2014 | B3: 0.442 | C3: -0.0425 | D3: 0.385 | E3: -0.025 | F3: 0.44 | G3: CFK
A4: 2015 | B4: 0.474 | C4: -0.06 | D4: 0.269 | E4: 0.027 | F4: 0.52 | G4: CFK/Macri
A5: 2016 | B5: 0.424 | C5: -0.0666 | D5: 0.41 | E5: -0.021 | F5: 0.54 | G5: Macri
A6: 2017 | B6: 0.418 | C6: -0.0669 | D6: 0.257 | E6: 0.029 | F6: 0.57 | G6: Macri
A7: 2018 | B7: 0.403 | C7: -0.0544 | D7: 0.476 | E7: -0.026 | F7: 0.86 | G7: Macri
A8: 2019 | B8: 0.436 | C8: -0.044 | D8: 0.538 | E8: -0.021 | F8: 0.9 | G8: Macri/AF
A9: 2020 | B9: 0.495 | C9: -0.0863 | D9: 0.361 | E9: -0.099 | F9: 1.03 | G9: A.Fernández
A10: 2021 | B10: 0.467 | C10: -0.0458 | D10: 0.509 | E10: 0.104 | F10: 0.8 | G10: A.Fernández
A11: 2022 | B11: 0.45 | C11: -0.0384 | D11: 0.948 | E11: 0.05 | F11: 0.77 | G11: A.Fernández
A12: 2023 | B12: 0.419 | C12: -0.029 | D12: 2.114 | E12: -0.016 | F12: 0.88 | G12: AF/Milei
A14: ABA 2: FORTALEZA (Dados e Fórmulas)
A15: Ano | B15: Rec. Nominal (bi) | C15: Deflator IPCA | D15: Rec. Real (2023) | E15: Fórmula Rec. Real | F15: Desp. Pessoal (mi) | G15: RCL (bi) | H15: % Desp. Pessoal | I15: Fórmula LRF | J15: Status LRF
A16: 2014 | B16: 3.82 | C16: 1853 | D16: 7.08 | E16: =B3*C3 -> -0.018785 | F16: 1.75 | G16: 3.8 | H16: 46.1% | I16: =(F16/G16)*100 -> 46.052632 | J16: Normal
A17: 2015 | B17: 4.05 | C17: 1729 | D17: 7.00 | E17: =B4*C4 -> -0.02844 | F17: 1.94 | G17: 4.04 | H17: 48.0% | I17: =(F17/G17)*100 -> 48.019802 | J17: Normal
A18: 2016 | B18: 4.28 | C18: 1620 | D18: 6.93 | E18: =B5*C5 -> -0.0282384 | F18: 2.01 | G18: 4.27 | H18: 47.1% | I18: =(F18/G18)*100 -> 47.0726 | J18: Normal
A19: 2017 | B19: 4.70 | C19: 1549 | D19: 7.28 | E19: =B6*C6 -> -0.0279642 | F19: 2.16 | G19: 4.69 | H19: 46.1% | I19: =(F19/G19)*100 -> 46.055437 | J19: Normal
A20: 2018 | B20: 5.10 | C20: 1481 | D20: 7.55 | E20: =B7*C7 -> -0.0219232 | F20: 2.44 | G20: 5.09 | H20: 47.9% | I20: =(F20/G20)*100 -> 47.937132 | J20: Normal
A21: 2019 | B21: 5.55 | C21: 1409 | D21: 7.82 | E21: =B8*C8 -> -0.019184 | F21: 2.71 | G21: 5.54 | H21: 48.9% | I21: =(F21/G21)*100 -> 48.916968 | J21: Normal
A22: 2020 | B22: 5.73 | C22: 1367 | D22: 7.83 | E22: =B9*C9 -> -0.0427185 | F22: 2.97 | G22: 5.72 | H22: 51.9% | I22: =(F22/G22)*100 -> 51.923077 | J22: Alerta
A23: 2021 | B23: 6.90 | C23: 1266 | D23: 8.73 | E23: =B10*C10 -> -0.0213886 | F23: 3.45 | G23: 6.89 | H23: 50.1% | I23: =(F23/G23)*100 -> 50.072569 | J23: Normal
A24: 2022 | B24: 8.20 | C24: 1123 | D24: 9.21 | E24: =B11*C11 -> -0.01728 | F24: 4.18 | G24: 8.19 | H24: 51.0% | I24: =(F24/G24)*100 -> 51.037851 | J24: Normal
A25: 2023 | B25: 9.50 | C25: 1000 | D25: 9.50 | E25: =B12*C12 -> -0.012151 | F25: 5.03 | G25: 9.49 | H25: 53.0% | I25: =(F25/G25)*100 -> 53.003161 | J25: Prudencial
A27: ABA 3: JUAZEIRO DO NORTE (Dados e Fórmulas)
A28: Ano | B28: Rec. Nominal (mi) | C28: Deflator IPCA | D28: Rec. Real (2023) | E28: Fórmula Rec. Real | F28: Desp. Pessoal (mi) | G28: RCL (mi) | H28: % Desp. Pessoal | I28: Fórmula LRF | J28: Status LRF
A29: 2014 | B29: 350 | C29: 1853 | D29: 648.6 | E29: =B3*C3 -> -0.018785 | F29: 154 | G29: 350 | H29: 0.44 | I29: =(F29/G29)*100 -> 44 | J29: Normal
A30: 2015 | B30: 370 | C30: 1729 | D30: 639.7 | E30: =B4*C4 -> -0.02844 | F30: 167 | G30: 370 | H30: 0.45 | I30: =(F30/G30)*100 -> 45.135135 | J30: Normal
A31: 2016 | B31: 390 | C31: 1620 | D31: 631.8 | E31: =B5*C5 -> -0.0282384 | F31: 179 | G31: 390 | H31: 0.46 | I31: =(F31/G31)*100 -> 45.897436 | J31: Normal
A32: 2017 | B32: 430 | C32: 1549 | D32: 666.1 | E32: =B6*C6 -> -0.0279642 | F32: 194 | G32: 430 | H32: 0.45 | I32: =(F32/G32)*100 -> 45.116279 | J32: Normal
A33: 2018 | B33: 480 | C33: 1481 | D33: 710.9 | E33: =B7*C7 -> -0.0219232 | F33: 221 | G33: 480 | H33: 0.46 | I33: =(F33/G33)*100 -> 46.041667 | J33: Normal
A34: 2019 | B34: 520 | C34: 1409 | D34: 732.7 | E34: =B8*C8 -> -0.019184 | F34: 244 | G34: 520 | H34: 0.47 | I34: =(F34/G34)*100 -> 46.923077 | J34: Normal
A35: 2020 | B35: 565 | C35: 1367 | D35: 772.4 | E35: =B9*C9 -> -0.0427185 | F35: 277 | G35: 565 | H35: 0.49 | I35: =(F35/G35)*100 -> 49.026549 | J35: Normal
A36: 2021 | B36: 700 | C36: 1266 | D36: 886.2 | E36: =B10*C10 -> -0.0213886 | F36: 329 | G36: 700 | H36: 0.47 | I36: =(F36/G36)*100 -> 47 | J36: Normal
A37: 2022 | B37: 920 | C37: 1123 | D37: 1033.2 | E37: =B11*C11 -> -0.01728 | F37: 423 | G37: 920 | H37: 0.46 | I37: =(F37/G37)*100 -> 45.978261 | J37: Normal
A38: 2023 | B38: 1060 | C38: 1000 | D38: 1060.0 | E38: =B12*C12 -> -0.012151 | F38: 498 | G38: 1060 | H38: 0.47 | I38: =(F38/G38)*100 -> 46.981132 | J38: Normal
A40: ABA 4: REGRESSÃO E LAFFER
A41: Indicador | B41: Valor | C41: Fórmula/Metodologia
A42: Elasticidade-Receita (beta1) | B42: 46235 | C42: ln(Receita_Real) = beta0 + beta1 * ln(PIB_Real)
A43: R-Quadrado (R2) | B43: 968 | C43: Medida de aderência do modelo
...

Sheet Planilha2
A1: Entidade | B1: Ano | C1: População (pessoas) | D1: Receita total bruta nominal (R$) | E1: Receita total bruta real (R$ 2025) | F1: Receita líquida estimada (R$ 2025) | G1: Receita tributária própria real (R$ 2025) | H1: Receita total bruta real per capita (R$ 2025/pessoa) | I1: Transferências da União real (R$ 2025) | J1: Transferências dos Estados real (R$ 2025) | K1: Despesa empenhada real (R$ 2025) | L1: Despesa liquidada real (R$ 2025) | M1: Despesa paga real (R$ 2025) | N1: DTP real (R$ 2025) | O1: RCL legal real (R$ 2025) | P1: DTP/RCL reportado (%) | Q1: PIB municipal nominal (R$) | R1: PIB municipal real (R$ 2025) | S1: PIB per capita publicado real (R$ 2025) | T1: IDEB municipal anos iniciais | U1: IDEB municipal anos finais | V1: ARCA total nominal normalizada (ARS) | W1: ARCA total real (ARS 2025) | X1: ARCA arrecadação real per capita (ARS 2025/pessoa) | Y1: RON amount (unidade/escala não declaradas) | Z1: Despesa governo geral (% PIB, FPP) | AA1: Saldo governo geral (% PIB, FMI FM) | AB1: Dívida bruta governo geral (% PIB) | AC1: Crescimento real PIB Argentina (%) | AD1: PIB nominal Argentina (US$ bilhões correntes) | AE1: Inflação média anual CPI (%) | AF1: Resultado primário SPN 2025 (ARS milhões) | AG1: Resultado financeiro SPN 2025 (ARS milhões)
A2: Fortaleza/CE | B2: 2014 | Q2: =IF('Dados tratados'!E160="","",'Dados tratados'!E160) -> 56116643786 | R2: =IF('Dados tratados'!G160="","",'Dados tratados'!G160) -> 1.0363846e+11 | S2: =IF('Dados tratados'!G161="","",'Dados tratados'!G161) -> 40296.516
A3: Fortaleza/CE | B3: 2015 | Q3: =IF('Dados tratados'!E168="","",'Dados tratados'!E168) -> 57211199796 | R3: =IF('Dados tratados'!G168="","",'Dados tratados'!G168) -> 9.6909133e+10 | S3: =IF('Dados tratados'!G169="","",'Dados tratados'!G169) -> 37399.501 | T3: =IF('Dados tratados'!J167="","",ROUND('Dados tratados'!J167,1)) -> 5.4 | U3: =IF('Dados tratados'!J166="","",ROUND('Dados tratados'!J166,1)) -> 4.4
A4: Fortaleza/CE | B4: 2016 | C4: =IF('Dados tratados'!E179="","",'Dados tratados'!E179) -> 2609716 | D4: =IF('Dados tratados'!E182="","",'Dados tratados'!E182) -> 6.6273005e+09 | E4: =IF('Dados tratados'!G182="","",'Dados tratados'!G182) -> 1.0323677e+10 | F4: =IF('Dados tratados'!G183="","",'Dados tratados'!G183) -> 9.7424977e+09 | G4: =IF('Dados tratados'!G170="","",'Dados tratados'!G170) -> 2.2559629e+09 | H4: =IF('Dados tratados'!I182="","",'Dados tratados'!I182) -> 3955.8622 | I4: =IF('Dados tratados'!G184="","",'Dados tratados'!G184) -> 2.7532171e+09 | J4: =IF('Dados tratados'!G185="","",'Dados tratados'!G185) -> 1.8392814e+09 | K4: =IF('Dados tratados'!G173="","",'Dados tratados'!G173) -> 9.4179207e+09 | L4: =IF('Dados tratados'!G174="","",'Dados tratados'!G174) -> 9.2848811e+09 | M4: =IF('Dados tratados'!G175="","",'Dados tratados'!G175) -> 9.2299266e+09 | N4: =IF('Dados tratados'!G176="","",'Dados tratados'!G176) -> 3.9152585e+09 | O4: =IF('Dados tratados'!G180="","",'Dados tratados'!G180) -> 8.3557614e+09 | P4: =IF('Dados tratados'!J171="","",'Dados tratados'!J171) -> 46.86 | Q4: =IF('Dados tratados'!E177="","",'Dados tratados'!E177) -> 60088000548 | R4: =IF('Dados tratados'!G177="","",'Dados tratados'!G177) -> 9.3602079e+10 | S4: =IF('Dados tratados'!G178="","",'Dados tratados'!G178) -> 35866.772
A5: Fortaleza/CE | B5: 2017 | C5: =IF('Dados tratados'!E201="","",'Dados tratados'!E201) -> 2627482 | D5: =IF('Dados tratados'!E204="","",'Dados tratados'!E204) -> 6.8105271e+09 | E5: =IF('Dados tratados'!G204="","",'Dados tratados'!G204) -> 1.025565e+10 | F5: =IF('Dados tratados'!G205="","",'Dados tratados'!G205) -> 9.6738059e+09 | G5: =IF('Dados tratados'!G186="","",'Dados tratados'!G186) -> 2.3807578e+09 | H5: =IF('Dados tratados'!I204="","",'Dados tratados'!I204) -> 3903.2238 | I5: =IF('Dados tratados'!G206="","",'Dados tratados'!G206) -> 2.7077916e+09 | J5: =IF('Dados tratados'!G207="","",'Dados tratados'!G207) -> 1.9246278e+09 | K5: =IF('Dados tratados'!G189="","",'Dados tratados'!G189) -> 9.8266791e+09 | L5: =IF('Dados tratados'!G190="","",'Dados tratados'!G190) -> 9.5890925e+09 | M5: =IF('Dados tratados'!G191="","",'Dados tratados'!G191) -> 9.496124e+09 | N5: =IF('Dados tratados'!G192="","",'Dados tratados'!G192) -> 3.9808051e+09 | O5: =IF('Dados tratados'!G202="","",'Dados tratados'!G202) -> 8.4610903e+09 | P5: =IF('Dados tratados'!J187="","",'Dados tratados'!J187) -> 47.05 | Q5: =IF('Dados tratados'!E199="","",'Dados tratados'!E199) -> 61592346898 | R5: =IF('Dados tratados'!G199="","",'Dados tratados'!G199) -> 9.2748998e+10 | S5: =IF('Dados tratados'!G200="","",'Dados tratados'!G200) -> 35299.58 | T5: =IF('Dados tratados'!J198="","",ROUND('Dados tratados'!J198,1)) -> 6 | U5: =IF('Dados tratados'!J197="","",ROUND('Dados tratados'!J197,1)) -> 4.9
A6: Fortaleza/CE | B6: 2018 | C6: =IF('Dados tratados'!E217="","",'Dados tratados'!E217) -> 2643247 | D6: =IF('Dados tratados'!E220="","",'Dados tratados'!E220) -> 7.4156614e+09 | E6: =IF('Dados tratados'!G220="","",'Dados tratados'!G220) -> 1.0772111e+10 | F6: =IF('Dados tratados'!G221="","",'Dados tratados'!G221) -> 1.0171016e+10 | G6: =IF('Dados tratados'!G208="","",'Dados tratados'!G208) -> 2.6586364e+09 | H6: =IF('Dados tratados'!I220="","",'Dados tratados'!I220) -> 4075.3329 | I6: =IF('Dados tratados'!G222="","",'Dados tratados'!G222) -> 2.8298095e+09 | J6: =IF('Dados tratados'!G223="","",'Dados tratados'!G223) -> 2.0184695e+09 | K6: =IF('Dados tratados'!G211="","",'Dados tratados'!G211) -> 9.9888541e+09 | L6: =IF('Dados tratados'!G212="","",'Dados tratados'!G212) -> 9.8365684e+09 | M6: =IF('Dados tratados'!G213="","",'Dados tratados'!G213) -> 9.7807949e+09 | N6: =IF('Dados tratados'!G214="","",'Dados tratados'!G214) -> 3.9956756e+09 | O6: =IF('Dados tratados'!G218="","",'Dados tratados'!G218) -> 8.8351908e+09 | P6: =IF('Dados tratados'!J209="","",'Dados tratados'!J209) -> 45.3 | Q6: =IF('Dados tratados'!E215="","",'Dados tratados'!E215) -> 66381302296 | R6: =IF('Dados tratados'!G215="","",'Dados tratados'!G215) -> 9.642657e+10 | S6: =IF('Dados tratados'!G216="","",'Dados tratados'!G216) -> 36480.341
A7: Fortaleza/CE | B7: 2019 | C7: =IF('Dados tratados'!E239="","",'Dados tratados'!E239) -> 2669342 | D7: =IF('Dados tratados'!E242="","",'Dados tratados'!E242) -> 8.558992e+09 | E7: =IF('Dados tratados'!G242="","",'Dados tratados'!G242) -> 1.1985516e+10 | F7: =IF('Dados tratados'!G243="","",'Dados tratados'!G243) -> 1.1361317e+10 | G7: =IF('Dados tratados'!G224="","",'Dados tratados'!G224) -> 2.7760298e+09 | H7: =IF('Dados tratados'!I242="","",'Dados tratados'!I242) -> 4490.0638 | I7: =IF('Dados tratados'!G244="","",'Dados tratados'!G244) -> 3.2396248e+09 | J7: =IF('Dados tratados'!G245="","",'Dados tratados'!G245) -> 2.0227615e+09 | K7: =IF('Dados tratados'!G227="","",'Dados tratados'!G227) -> 1.149326e+10 | L7: =IF('Dados tratados'!G228="","",'Dados tratados'!G228) -> 1.0969122e+10 | M7: =IF('Dados tratados'!G229="","",'Dados tratados'!G229) -> 1.0881689e+10 | N7: =IF('Dados tratados'!G230="","",'Dados tratados'!G230) -> 4.0795261e+09 | O7: =IF('Dados tratados'!G240="","",'Dados tratados'!G240) -> 9.6692359e+09 | P7: =IF('Dados tratados'!J225="","",'Dados tratados'!J225) -> 42.31 | Q7: =IF('Dados tratados'!E237="","",'Dados tratados'!E237) -> 67401429903 | R7: =IF('Dados tratados'!G237="","",'Dados tratados'!G237) -> 9.4385052e+10 | S7: =IF('Dados tratados'!G238="","",'Dados tratados'!G238) -> 35358.915 | T7: =IF('Dados tratados'!J236="","",ROUND('Dados tratados'!J236,1)) -> 6.2 | U7: =IF('Dados tratados'!J235="","",ROUND('Dados tratados'!J235,1)) -> 5.2
A8: Fortaleza/CE | B8: 2020 | C8: =IF('Dados tratados'!E255="","",'Dados tratados'!E255) -> 2686612 | D8: =IF('Dados tratados'!E258="","",'Dados tratados'!E258) -> 8.7207581e+09 | E8: =IF('Dados tratados'!G258="","",'Dados tratados'!G258) -> 1.1832026e+10 | F8: =IF('Dados tratados'!G259="","",'Dados tratados'!G259) -> 1.123607e+10 | G8: =IF('Dados tratados'!G246="","",'Dados tratados'!G246) -> 2.6337637e+09 | H8: =IF('Dados tratados'!I258="","",'Dados tratados'!I258) -> 4404.0697 | I8: =IF('Dados tratados'!G260="","",'Dados tratados'!G260) -> 4.0355661e+09 | J8: =IF('Dados tratados'!G261="","",'Dados tratados'!G261) -> 1.9078859e+09 | K8: =IF('Dados tratados'!G249="","",'Dados tratados'!G249) -> 1.2257284e+10 | L8: =IF('Dados tratados'!G250="","",'Dados tratados'!G250) -> 1.1733902e+10 | M8: =IF('Dados tratados'!G251="","",'Dados tratados'!G251) -> 1.1694119e+10 | N8: =IF('Dados tratados'!G252="","",'Dados tratados'!G252) -> 4.4387735e+09 | O8: =IF('Dados tratados'!G256="","",'Dados tratados'!G256) -> 9.6456629e+09 | P8: =IF('Dados tratados'!J247="","",'Dados tratados'!J247) -> 46.03 | Q8: =IF('Dados tratados'!E253="","",'Dados tratados'!E253) -> 64821581710 | R8: =IF('Dados tratados'!G253="","",'Dados tratados'!G253) -> 8.7947706e+10 | S8: =IF('Dados tratados'!G254="","",'Dados tratados'!G254) -> 32735.544
A9: Fortaleza/CE | B9: 2021 | C9: =IF('Dados tratados'!E277="","",'Dados tratados'!E277) -> 2703391 | D9: =IF('Dados tratados'!E280="","",'Dados tratados'!E280) -> 9.5594381e+09 | E9: =IF('Dados tratados'!G280="","",'Dados tratados'!G280) -> 1.1975734e+10 | F9: =IF('Dados tratados'!G281="","",'Dados tratados'!G281) -> 1.1292289e+10 | G9: =IF('Dados tratados'!G262="","",'Dados tratados'!G262) -> 2.895323e+09 | H9: =IF('Dados tratados'!I280="","",'Dados tratados'!I280) -> 4429.8935 | I9: =IF('Dados tratados'!G282="","",'Dados tratados'!G282) -> 3.5274361e+09 | J9: =IF('Dados tratados'!G283="","",'Dados tratados'!G283) -> 2.117125e+09 | K9: =IF('Dados tratados'!G265="","",'Dados tratados'!G265) -> 1.1534366e+10 | L9: =IF('Dados tratados'!G266="","",'Dados tratados'!G266) -> 1.0910318e+10 | M9: =IF('Dados tratados'!G267="","",'Dados tratados'!G267) -> 1.0810448e+10 | N9: =IF('Dados tratados'!G268="","",'Dados tratados'!G268) -> 4.4229267e+09 | O9: =IF('Dados tratados'!G278="","",'Dados tratados'!G278) -> 9.6491504e+09 | P9: =IF('Dados tratados'!J263="","",'Dados tratados'!J263) -> 45.88 | Q9: =IF('Dados tratados'!E275="","",'Dados tratados'!E275) -> 73437738924 | R9: =IF('Dados tratados'!G275="","",'Dados tratados'!G275) -> 9.2000265e+10 | S9: =IF('Dados tratados'!G276="","",'Dados tratados'!G276) -> 34031.437 | T9: =IF('Dados tratados'!J274="","",ROUND('Dados tratados'!J274,1)) -> 5.8 | U9: =IF('Dados tratados'!J273="","",ROUND('Dados tratados'!J273,1)) -> 5.2
A10: Fortaleza/CE | B10: 2022 | C10: =IF('Dados tratados'!E293="","",'Dados tratados'!E293) -> 2428708 | D10: =IF('Dados tratados'!E296="","",'Dados tratados'!E296) -> 1.098491e+10 | E10: =IF('Dados tratados'!G296="","",'Dados tratados'!G296) -> 1.2592884e+10 | F10: =IF('Dados tratados'!G297="","",'Dados tratados'!G297) -> 1.1914792e+10 | G10: =IF('Dados tratados'!G284="","",'Dados tratados'!G284) -> 3.0969001e+09 | H10: =IF('Dados tratados'!I296="","",'Dados tratados'!I296) -> 5185.0135 | I10: =IF('Dados tratados'!G298="","",'Dados tratados'!G298) -> 3.7593429e+09 | J10: =IF('Dados tratados'!G299="","",'Dados tratados'!G299) -> 1.9780526e+09 | K10: =IF('Dados tratados'!G287="","",'Dados tratados'!G287) -> 1.1790015e+10 | L10: =IF('Dados tratados'!G288="","",'Dados tratados'!G288) -> 1.1613264e+10 | M10: =IF('Dados tratados'!G289="","",'Dados tratados'!G289) -> 1.1499776e+10 | N10: =IF('Dados tratados'!G290="","",'Dados tratados'!G290) -> 5.0484748e+09 | O10: =IF('Dados tratados'!G294="","",'Dados tratados'!G294) -> 1.0237464e+10 | P10: =IF('Dados tratados'!J285="","",'Dados tratados'!J285) -> 49.34 | Q10: =IF('Dados tratados'!E291="","",'Dados tratados'!E291) -> 81362332600 | R10: =IF('Dados tratados'!G291="","",'Dados tratados'!G291) -> 9.3272166e+10 | S10: =IF('Dados tratados'!G292="","",'Dados tratados'!G292) -> 38404.505
A11: Fortaleza/CE | B11: 2023 | C11: =IF('Dados tratados'!E315="","",'Dados tratados'!E315) | D11: =IF('Dados tratados'!E318="","",'Dados tratados'!E318) -> 1.3483834e+10 | E11: =IF('Dados tratados'!G318="","",'Dados tratados'!G318) -> 1.477873e+10 | F11: =IF('Dados tratados'!G319="","",'Dados tratados'!G319) -> 1.4107822e+10 | G11: =IF('Dados tratados'!G300="","",'Dados tratados'!G300) -> 3.5773553e+09 | H11: =IF('Dados tratados'!I318="","",'Dados tratados'!I318) | I11: =IF('Dados tratados'!G320="","",'Dados tratados'!G320) -> 4.0970883e+09 | J11: =IF('Dados tratados'!G321="","",'Dados tratados'!G321) -> 1.8658732e+09 | K11: =IF('Dados tratados'!G303="","",'Dados tratados'!G303) -> 1.346842e+10 | L11: =IF('Dados tratados'!G304="","",'Dados tratados'!G304) -> 1.3208965e+10 | M11: =IF('Dados tratados'!G305="","",'Dados tratados'!G305) -> 1.3070283e+10 | N11: =IF('Dados tratados'!G306="","",'Dados tratados'!G306) -> 5.2730769e+09 | O11: =IF('Dados tratados'!G316="","",'Dados tratados'!G316) -> 1.1081711e+10 | P11: =IF('Dados tratados'!J301="","",'Dados tratados'!J301) -> 48.38 | Q11: =IF('Dados tratados'!E313="","",'Dados tratados'!E313) -> 86939831736 | R11: =IF('Dados tratados'!G313="","",'Dados tratados'!G313) -> 9.5288944e+10 | S11: =IF('Dados tratados'!G314="","",'Dados tratados'!G314) -> 39234.416 | T11: =IF('Dados tratados'!J312="","",ROUND('Dados tratados'!J312,1)) -> 5.9 | U11: =IF('Dados tratados'!J311="","",ROUND('Dados tratados'!J311,1)) -> 5.2
A12: Fortaleza/CE | B12: 2024 | C12: =IF('Dados tratados'!E329="","",'Dados tratados'!E329) -> 2574412 | D12: =IF('Dados tratados'!E332="","",'Dados tratados'!E332) -> 1.4142951e+10 | E12: =IF('Dados tratados'!G332="","",'Dados tratados'!G332) -> 1.4852468e+10 | F12: =IF('Dados tratados'!G333="","",'Dados tratados'!G333) -> 1.4121629e+10 | G12: =IF('Dados tratados'!G322="","",'Dados tratados'!G322) -> 3.7724908e+09 | H12: =IF('Dados tratados'!I332="","",'Dados tratados'!I332) -> 5769.2662 | I12: =IF('Dados tratados'!G334="","",'Dados tratados'!G334) -> 4.499525e+09 | J12: =IF('Dados tratados'!G335="","",'Dados tratados'!G335) -> 1.9807453e+09 | K12: =IF('Dados tratados'!G325="","",'Dados tratados'!G325) -> 1.4981082e+10 | L12: =IF('Dados tratados'!G326="","",'Dados tratados'!G326) -> 1.4651817e+10 | M12: =IF('Dados tratados'!G327="","",'Dados tratados'!G327) -> 1.4613053e+10 | N12: =IF('Dados tratados'!G328="","",'Dados tratados'!G328) -> 5.6710914e+09 | O12: =IF('Dados tratados'!G330="","",'Dados tratados'!G330) -> 1.2012218e+10 | P12: =IF('Dados tratados'!J323="","",'Dados tratados'!J323) -> 47.87
A13: Fortaleza/CE | B13: 2025 | C13: =IF('Dados tratados'!E349="","",'Dados tratados'!E349) -> 2578483 | D13: =IF('Dados tratados'!E352="","",'Dados tratados'!E352) -> 1.5325828e+10 | E13: =IF('Dados tratados'!G352="","",'Dados tratados'!G352) -> 1.5325828e+10 | F13: =IF('Dados tratados'!G353="","",'Dados tratados'!G353) -> 1.4587635e+10 | G13: =IF('Dados tratados'!G336="","",'Dados tratados'!G336) -> 3.739861e+09 | H13: =IF('Dados tratados'!I352="","",'Dados tratados'!I352) -> 5943.7381 | I13: =IF('Dados tratados'!G354="","",'Dados tratados'!G354) -> 4.9991481e+09 | J13: =IF('Dados tratados'!G355="","",'Dados tratados'!G355) -> 2.0175946e+09 | K13: =IF('Dados tratados'!G339="","",'Dados tratados'!G339) -> 1.3965277e+10 | L13: =IF('Dados tratados'!G340="","",'Dados tratados'!G340) -> 1.378918e+10 | M13: =IF('Dados tratados'!G341="","",'Dados tratados'!G341) -> 1.3760844e+10 | N13: =IF('Dados tratados'!G342="","",'Dados tratados'!G342) -> 5.7142353e+09 | O13: =IF('Dados tratados'!G350="","",'Dados tratados'!G350) -> 1.2539078e+10 | P13: =IF('Dados tratados'!J337="","",'Dados tratados'!J337) -> 46.54 | T13: =IF('Dados tratados'!J348="","",ROUND('Dados tratados'!J348,1)) -> 6.1 | U13: =IF('Dados tratados'!J347="","",ROUND('Dados tratados'!J347,1)) -> 5.2
A14: Juazeiro do Norte/CE | B14: 2014 | Q14: =IF('Dados tratados'!E395="","",'Dados tratados'!E395) -> 3819081571 | R14: =IF('Dados tratados'!G395="","",'Dados tratados'!G395) -> 7.0532326e+09 | S14: =IF('Dados tratados'!G396="","",'Dados tratados'!G396) -> 26746.786
A15: Juazeiro do Norte/CE | B15: 2015 | Q15: =IF('Dados tratados'!E403="","",'Dados tratados'!E403) -> 3921616173 | R15: =IF('Dados tratados'!G403="","",'Dados tratados'!G403) -> 6.6427627e+09 | S15: =IF('Dados tratados'!G404="","",'Dados tratados'!G404) -> 24970.729 | T15: =IF('Dados tratados'!J402="","",ROUND('Dados tratados'!J402,1)) -> 4.9 | U15: =IF('Dados tratados'!J401="","",ROUND('Dados tratados'!J401,1)) -> 4.3
A16: Juazeiro do Norte/CE | B16: 2016 | C16: =IF('Dados tratados'!E414="","",'Dados tratados'!E414) -> 268248 | D16: =IF('Dados tratados'!E417="","",'Dados tratados'!E417) -> 539074379 | E16: =IF('Dados tratados'!G417="","",'Dados tratados'!G417) -> 8.3974308e+08 | F16: =IF('Dados tratados'!G418="","",'Dados tratados'!G418) -> 7.9237032e+08 | G16: =IF('Dados tratados'!G405="","",'Dados tratados'!G405) -> 72342465 | H16: =IF('Dados tratados'!I417="","",'Dados tratados'!I417) -> 3130.4729 | I16: =IF('Dados tratados'!G419="","",'Dados tratados'!G419) -> 2.8522777e+08 | J16: =IF('Dados tratados'!G420="","",'Dados tratados'!G420) -> 1.103324e+08 | K16: =IF('Dados tratados'!G408="","",'Dados tratados'!G408) -> 7.2510464e+08 | L16: =IF('Dados tratados'!G409="","",'Dados tratados'!G409) -> 7.1700376e+08 | M16: =IF('Dados tratados'!G410="","",'Dados tratados'!G410) -> 6.5633516e+08 | N16: =IF('Dados tratados'!G411="","",'Dados tratados'!G411) -> 3.5929762e+08 | O16: =IF('Dados tratados'!G415="","",'Dados tratados'!G415) -> 6.8314874e+08 | P16: =IF('Dados tratados'!J406="","",'Dados tratados'!J406) -> 52.59 | Q16: =IF('Dados tratados'!E412="","",'Dados tratados'!E412) -> 4183987276 | R16: =IF('Dados tratados'!G412="","",'Dados tratados'!G412) -> 6.5176059e+09 | S16: =IF('Dados tratados'!G413="","",'Dados tratados'!G413) -> 24296.942
A17: Juazeiro do Norte/CE | B17: 2017 | C17: =IF('Dados tratados'!E436="","",'Dados tratados'!E436) -> 270383 | D17: =IF('Dados tratados'!E439="","",'Dados tratados'!E439) -> 6.7295029e+08 | E17: =IF('Dados tratados'!G439="","",'Dados tratados'!G439) -> 1.013364e+09 | F17: =IF('Dados tratados'!G440="","",'Dados tratados'!G440) -> 9.6715338e+08 | G17: =IF('Dados tratados'!G421="","",'Dados tratados'!G421) -> 98386675 | H17: =IF('Dados tratados'!I439="","",'Dados tratados'!I439) -> 3747.8834 | I17: =IF('Dados tratados'!G441="","",'Dados tratados'!G441) -> 2.7073559e+08 | J17: =IF('Dados tratados'!G442="","",'Dados tratados'!G442) -> 1.1511758e+08 | K17: =IF('Dados tratados'!G424="","",'Dados tratados'!G424) -> 7.871231e+08 | L17: =IF('Dados tratados'!G425="","",'Dados tratados'!G425) -> 7.5632053e+08 | M17: =IF('Dados tratados'!G426="","",'Dados tratados'!G426) -> 7.2656917e+08 | N17: =IF('Dados tratados'!G427="","",'Dados tratados'!G427) -> 3.5977883e+08 | O17: =IF('Dados tratados'!G437="","",'Dados tratados'!G437) -> 8.8170013e+08 | P17: =IF('Dados tratados'!J422="","",'Dados tratados'!J422) -> 40.81 | Q17: =IF('Dados tratados'!E434="","",'Dados tratados'!E434) -> 4428413505 | R17: =IF('Dados tratados'!G434="","",'Dados tratados'!G434) -> 6.6685382e+09 | S17: =IF('Dados tratados'!G435="","",'Dados tratados'!G435) -> 24663.306 | T17: =IF('Dados tratados'!J433="","",ROUND('Dados tratados'!J433,1)) -> 5 | U17: =IF('Dados tratados'!J432="","",ROUND('Dados tratados'!J432,1)) -> 4.3
A18: Juazeiro do Norte/CE | B18: 2018 | C18: =IF('Dados tratados'!E452="","",'Dados tratados'!E452) -> 271926 | D18: =IF('Dados tratados'!E455="","",'Dados tratados'!E455) -> 5.8221709e+08 | E18: =IF('Dados tratados'!G455="","",'Dados tratados'!G455) -> 8.4573811e+08 | F18: =IF('Dados tratados'!G456="","",'Dados tratados'!G456) -> 7.9833104e+08 | G18: =IF('Dados tratados'!G443="","",'Dados tratados'!G443) -> 1.0584853e+08 | H18: =IF('Dados tratados'!I455="","",'Dados tratados'!I455) -> 3110.1774 | I18: =IF('Dados tratados'!G457="","",'Dados tratados'!G457) -> 3.1141507e+08 | J18: =IF('Dados tratados'!G458="","",'Dados tratados'!G458) -> 1.1535627e+08 | K18: =IF('Dados tratados'!G446="","",'Dados tratados'!G446) -> 8.0140874e+08 | L18: =IF('Dados tratados'!G447="","",'Dados tratados'!G447) -> 7.6849754e+08 | M18: =IF('Dados tratados'!G448="","",'Dados tratados'!G448) -> 7.3019675e+08 | N18: =IF('Dados tratados'!G449="","",'Dados tratados'!G449) -> 3.8749214e+08 | O18: =IF('Dados tratados'!G453="","",'Dados tratados'!G453) -> 7.1888268e+08 | P18: =IF('Dados tratados'!J444="","",'Dados tratados'!J444) -> 53.9 | Q18: =IF('Dados tratados'!E450="","",'Dados tratados'!E450) -> 4815934956 | R18: =IF('Dados tratados'!G450="","",'Dados tratados'!G450) -> 6.9957062e+09 | S18: =IF('Dados tratados'!G451="","",'Dados tratados'!G451) -> 25726.505
A19: Juazeiro do Norte/CE | B19: 2019 | C19: =IF('Dados tratados'!E474="","",'Dados tratados'!E474) -> 274207 | D19: =IF('Dados tratados'!E477="","",'Dados tratados'!E477) -> 6.3174651e+08 | E19: =IF('Dados tratados'!G477="","",'Dados tratados'!G477) -> 8.8466117e+08 | F19: =IF('Dados tratados'!G478="","",'Dados tratados'!G478) -> 8.3584521e+08 | G19: =IF('Dados tratados'!G459="","",'Dados tratados'!G459) -> 1.1137952e+08 | H19: =IF('Dados tratados'!I477="","",'Dados tratados'!I477) -> 3226.253 | I19: =IF('Dados tratados'!G479="","",'Dados tratados'!G479) -> 3.2548416e+08 | J19: =IF('Dados tratados'!G480="","",'Dados tratados'!G480) -> 1.1545436e+08 | K19: =IF('Dados tratados'!G462="","",'Dados tratados'!G462) -> 8.3025852e+08 | L19: =IF('Dados tratados'!G463="","",'Dados tratados'!G463) -> 7.8505918e+08 | M19: =IF('Dados tratados'!G464="","",'Dados tratados'!G464) -> 7.3096158e+08 | N19: =IF('Dados tratados'!G465="","",'Dados tratados'!G465) -> 4.0091274e+08 | O19: =IF('Dados tratados'!G475="","",'Dados tratados'!G475) -> 7.5689648e+08 | P19: =IF('Dados tratados'!J460="","",'Dados tratados'!J460) -> 52.97 | Q19: =IF('Dados tratados'!E472="","",'Dados tratados'!E472) -> 4868984226 | R19: =IF('Dados tratados'!G472="","",'Dados tratados'!G472) -> 6.8182431e+09 | S19: =IF('Dados tratados'!G473="","",'Dados tratados'!G473) -> 24865.313 | T19: =IF('Dados tratados'!J471="","",ROUND('Dados tratados'!J471,1)) -> 5.5 | U19: =IF('Dados tratados'!J470="","",ROUND('Dados tratados'!J470,1)) -> 4.8
A20: Juazeiro do Norte/CE | B20: 2020 | C20: =IF('Dados tratados'!E490="","",'Dados tratados'!E490) -> 276264 | D20: =IF('Dados tratados'!E493="","",'Dados tratados'!E493) -> 6.5518473e+08 | E20: =IF('Dados tratados'!G493="","",'Dados tratados'!G493) -> 8.8893225e+08 | F20: =IF('Dados tratados'!G494="","",'Dados tratados'!G494) -> 8.4322738e+08 | G20: =IF('Dados tratados'!G481="","",'Dados tratados'!G481) -> 1.1255169e+08 | H20: =IF('Dados tratados'!I493="","",'Dados tratados'!I493) -> 3217.6912 | I20: =IF('Dados tratados'!G495="","",'Dados tratados'!G495) -> 3.8946613e+08 | J20: =IF('Dados tratados'!G496="","",'Dados tratados'!G496) -> 1.122299e+08 | K20: =IF('Dados tratados'!G484="","",'Dados tratados'!G484) -> 9.1388185e+08 | L20: =IF('Dados tratados'!G485="","",'Dados tratados'!G485) -> 8.9994465e+08 | M20: =IF('Dados tratados'!G486="","",'Dados tratados'!G486) -> 8.2561105e+08 | N20: =IF('Dados tratados'!G487="","",'Dados tratados'!G487) -> 4.5183482e+08 | O20: =IF('Dados tratados'!G491="","",'Dados tratados'!G491) -> 7.5876554e+08 | P20: =IF('Dados tratados'!J482="","",'Dados tratados'!J482) -> 60.24 | Q20: =IF('Dados tratados'!E488="","",'Dados tratados'!E488) -> 4827915153 | R20: =IF('Dados tratados'!G488="","",'Dados tratados'!G488) -> 6.5503503e+09 | S20: =IF('Dados tratados'!G489="","",'Dados tratados'!G489) -> 23710.473
A21: Juazeiro do Norte/CE | B21: 2021 | C21: =IF('Dados tratados'!E512="","",'Dados tratados'!E512) -> 278264 | D21: =IF('Dados tratados'!E515="","",'Dados tratados'!E515) -> 7.6166722e+08 | E21: =IF('Dados tratados'!G515="","",'Dados tratados'!G515) -> 9.5419041e+08 | F21: =IF('Dados tratados'!G516="","",'Dados tratados'!G516) -> 9.0041637e+08 | G21: =IF('Dados tratados'!G497="","",'Dados tratados'!G497) -> 1.3314673e+08 | H21: =IF('Dados tratados'!I515="","",'Dados tratados'!I515) -> 3429.0832 | I21: =IF('Dados tratados'!G517="","",'Dados tratados'!G517) -> 3.6770209e+08 | J21: =IF('Dados tratados'!G518="","",'Dados tratados'!G518) -> 1.2467156e+08 | K21: =IF('Dados tratados'!G500="","",'Dados tratados'!G500) -> 8.2477803e+08 | L21: =IF('Dados tratados'!G501="","",'Dados tratados'!G501) -> 8.1132105e+08 | M21: =IF('Dados tratados'!G502="","",'Dados tratados'!G502) -> 7.4548313e+08 | N21: =IF('Dados tratados'!G503="","",'Dados tratados'!G503) -> 4.165705e+08 | O21: =IF('Dados tratados'!G513="","",'Dados tratados'!G513) -> 7.8508693e+08 | P21: =IF('Dados tratados'!J498="","",'Dados tratados'!J498) -> 53.21 | Q21: =IF('Dados tratados'!E510="","",'Dados tratados'!E510) -> 5114785978 | R21: =IF('Dados tratados'!G510="","",'Dados tratados'!G510) -> 6.4076274e+09 | S21: =IF('Dados tratados'!G511="","",'Dados tratados'!G511) -> 23027.158 | T21: =IF('Dados tratados'!J509="","",ROUND('Dados tratados'!J509,1)) -> 5.4 | U21: =IF('Dados tratados'!J508="","",ROUND('Dados tratados'!J508,1)) -> 5
A22: Juazeiro do Norte/CE | B22: 2022 | C22: =IF('Dados tratados'!E528="","",'Dados tratados'!E528) -> 286120 | D22: =IF('Dados tratados'!E531="","",'Dados tratados'!E531) -> 9.5620978e+08 | E22: =IF('Dados tratados'!G531="","",'Dados tratados'!G531) -> 1.09618e+09 | F22: =IF('Dados tratados'!G532="","",'Dados tratados'!G532) -> 1.0383755e+09 | G22: =IF('Dados tratados'!G519="","",'Dados tratados'!G519) -> 1.607558e+08 | H22: =IF('Dados tratados'!I531="","",'Dados tratados'!I531) -> 3831.1895 | I22: =IF('Dados tratados'!G533="","",'Dados tratados'!G533) -> 4.2260821e+08 | J22: =IF('Dados tratados'!G534="","",'Dados tratados'!G534) -> 1.2212856e+08 | K22: =IF('Dados tratados'!G522="","",'Dados tratados'!G522) -> 9.52252e+08 | L22: =IF('Dados tratados'!G523="","",'Dados tratados'!G523) -> 9.4192029e+08 | M22: =IF('Dados tratados'!G524="","",'Dados tratados'!G524) -> 9.017633e+08 | N22: =IF('Dados tratados'!G525="","",'Dados tratados'!G525) -> 4.7990483e+08 | O22: =IF('Dados tratados'!G529="","",'Dados tratados'!G529) -> 8.912051e+08 | P22: =IF('Dados tratados'!J520="","",'Dados tratados'!J520) -> 53.88 | Q22: =IF('Dados tratados'!E526="","",'Dados tratados'!E526) -> 5783730209 | R22: =IF('Dados tratados'!G526="","",'Dados tratados'!G526) -> 6.6303537e+09 | S22: =IF('Dados tratados'!G527="","",'Dados tratados'!G527) -> 23173.33
A23: Juazeiro do Norte/CE | B23: 2023 | C23: =IF('Dados tratados'!E550="","",'Dados tratados'!E550) | D23: =IF('Dados tratados'!E553="","",'Dados tratados'!E553) -> 1.0051759e+09 | E23: =IF('Dados tratados'!G553="","",'Dados tratados'!G553) -> 1.1017062e+09 | F23: =IF('Dados tratados'!G554="","",'Dados tratados'!G554) -> 1.0442806e+09 | G23: =IF('Dados tratados'!G535="","",'Dados tratados'!G535) -> 1.7593054e+08 | H23: =IF('Dados tratados'!I553="","",'Dados tratados'!I553) | I23: =IF('Dados tratados'!G555="","",'Dados tratados'!G555) -> 4.307229e+08 | J23: =IF('Dados tratados'!G556="","",'Dados tratados'!G556) -> 1.2527713e+08 | K23: =IF('Dados tratados'!G538="","",'Dados tratados'!G538) -> 1.0015591e+09 | L23: =IF('Dados tratados'!G539="","",'Dados tratados'!G539) -> 9.8737728e+08 | M23: =IF('Dados tratados'!G540="","",'Dados tratados'!G540) -> 9.4330299e+08 | N23: =IF('Dados tratados'!G541="","",'Dados tratados'!G541) -> 4.5771223e+08 | O23: =IF('Dados tratados'!G551="","",'Dados tratados'!G551) -> 8.8029671e+08 | P23: =IF('Dados tratados'!J536="","",'Dados tratados'!J536) -> 53.78 | Q23: =IF('Dados tratados'!E548="","",'Dados tratados'!E548) -> 6457542671 | R23: =IF('Dados tratados'!G548="","",'Dados tratados'!G548) -> 7.0776813e+09 | S23: =IF('Dados tratados'!G549="","",'Dados tratados'!G549) -> 24736.757 | T23: =IF('Dados tratados'!J547="","",ROUND('Dados tratados'!J547,1)) -> 5.5 | U23: =IF('Dados tratados'!J546="","",ROUND('Dados tratados'!J546,1)) -> 4.9
A24: Juazeiro do Norte/CE | B24: 2024 | C24: =IF('Dados tratados'!E564="","",'Dados tratados'!E564) -> 303004 | D24: =IF('Dados tratados'!E567="","",'Dados tratados'!E567) -> 1.1806379e+09 | E24: =IF('Dados tratados'!G567="","",'Dados tratados'!G567) -> 1.2398676e+09 | F24: =IF('Dados tratados'!G568="","",'Dados tratados'!G568) -> 1.1779188e+09 | G24: =IF('Dados tratados'!G557="","",'Dados tratados'!G557) -> 1.8410232e+08 | H24: =IF('Dados tratados'!I567="","",'Dados tratados'!I567) -> 4091.9184 | I24: =IF('Dados tratados'!G569="","",'Dados tratados'!G569) -> 5.0272049e+08 | J24: =IF('Dados tratados'!G570="","",'Dados tratados'!G570) -> 1.3090848e+08 | K24: =IF('Dados tratados'!G560="","",'Dados tratados'!G560) -> 1.1519602e+09 | L24: =IF('Dados tratados'!G561="","",'Dados tratados'!G561) -> 1.1371512e+09 | M24: =IF('Dados tratados'!G562="","",'Dados tratados'!G562) -> 1.098317e+09 | N24: =IF('Dados tratados'!G563="","",'Dados tratados'!G563) -> 4.7663873e+08 | O24: =IF('Dados tratados'!G565="","",'Dados tratados'!G565) -> 1.0082374e+09 | P24: =IF('Dados tratados'!J558="","",'Dados tratados'!J558) -> 48.8
A25: Juazeiro do Norte/CE | B25: 2025 | C25: =IF('Dados tratados'!E584="","",'Dados tratados'!E584) -> 305531 | D25: =IF('Dados tratados'!E587="","",'Dados tratados'!E587) -> 1.3114161e+09 | E25: =IF('Dados tratados'!G587="","",'Dados tratados'!G587) -> 1.3114161e+09 | F25: =IF('Dados tratados'!G588="","",'Dados tratados'!G588) -> 1.247858e+09 | G25: =IF('Dados tratados'!G571="","",'Dados tratados'!G571) -> 2.1317204e+08 | H25: =IF('Dados tratados'!I587="","",'Dados tratados'!I587) -> 4292.252 | I25: =IF('Dados tratados'!G589="","",'Dados tratados'!G589) -> 5.3016049e+08 | J25: =IF('Dados tratados'!G590="","",'Dados tratados'!G590) -> 1.3407585e+08 | K25: =IF('Dados tratados'!G574="","",'Dados tratados'!G574) -> 1.1693958e+09 | L25: =IF('Dados tratados'!G575="","",'Dados tratados'!G575) -> 1.1467558e+09 | M25: =IF('Dados tratados'!G576="","",'Dados tratados'!G576) -> 1.1103404e+09 | N25: =IF('Dados tratados'!G577="","",'Dados tratados'!G577) -> 4.9204277e+08 | O25: =IF('Dados tratados'!G585="","",'Dados tratados'!G585) -> 1.0484594e+09 | P25: =IF('Dados tratados'!J572="","",'Dados tratados'!J572) -> 48.18 | T25: =IF('Dados tratados'!J583="","",ROUND('Dados tratados'!J583,1)) -> 5.6 | U25: =IF('Dados tratados'!J582="","",ROUND('Dados tratados'!J582,1)) -> 4.9
A26: Argentina | B26: 2014
A27: Argentina | B27: 2015
A28: Argentina | B28: 2016 | C28: =IF('Dados tratados'!E10="","",'Dados tratados'!E10) -> 43590000 | V28: =IF('Dados tratados'!E2="","",'Dados tratados'!E2) -> 2.2730474e+12 | W28: =IF('Dados tratados'!G2="","",'Dados tratados'!G2) -> 2.268147e+14 | X28: =IF('Dados tratados'!I2="","",'Dados tratados'!I2) -> 5203365.4 | Y28: =IF('Dados tratados'!J11="","",'Dados tratados'!J11) -> 1120751.4 | Z28: =IF('Dados tratados'!J6="","",'Dados tratados'!J6) -> 41.522021 | AA28: =IF('Dados tratados'!J9="","",'Dados tratados'!J9) -> -6.654669 | AB28: =IF('Dados tratados'!J7="","",'Dados tratados'!J7) -> 53.1 | AC28: =IF('Dados tratados'!J5="","",'Dados tratados'!J5) -> -2.1 | AD28: =IF('Dados tratados'!J4="","",'Dados tratados'!J4) -> 556.774 | AE28: =IF('Dados tratados'!J3="","",'Dados tratados'!J3) | AF28: =IF('Dados tratados'!D13="","",'Dados tratados'!D13) | AG28: =IF('Dados tratados'!D12="","",'Dados tratados'!D12)
A29: Argentina | B29: 2017 | C29: =IF('Dados tratados'!E22="","",'Dados tratados'!E22) -> 44045000 | V29: =IF('Dados tratados'!E14="","",'Dados tratados'!E14) -> 2.8422167e+12 | W29: =IF('Dados tratados'!G14="","",'Dados tratados'!G14) -> 2.2562365e+14 | X29: =IF('Dados tratados'!I14="","",'Dados tratados'!I14) -> 5122571.1 | Y29: =IF('Dados tratados'!J23="","",'Dados tratados'!J23) -> 1457199.8 | Z29: =IF('Dados tratados'!J18="","",'Dados tratados'!J18) -> 41.121454 | AA29: =IF('Dados tratados'!J21="","",'Dados tratados'!J21) -> -6.6933411 | AB29: =IF('Dados tratados'!J19="","",'Dados tratados'!J19) -> 57 | AC29: =IF('Dados tratados'!J17="","",'Dados tratados'!J17) -> 2.8 | AD29: =IF('Dados tratados'!J16="","",'Dados tratados'!J16) -> 643.861 | AE29: =IF('Dados tratados'!J15="","",'Dados tratados'!J15) -> 25.7 | AF29: =IF('Dados tratados'!D25="","",'Dados tratados'!D25) | AG29: =IF('Dados tratados'!D24="","",'Dados tratados'!D24)
A30: Argentina | B30: 2018 | C30: =IF('Dados tratados'!E34="","",'Dados tratados'!E34) -> 44495000 | V30: =IF('Dados tratados'!E26="","",'Dados tratados'!E26) -> 3.7134091e+12 | W30: =IF('Dados tratados'!G26="","",'Dados tratados'!G26) -> 219494786934247 | X30: =IF('Dados tratados'!I26="","",'Dados tratados'!I26) -> 4933021.4 | Y30: =IF('Dados tratados'!J35="","",'Dados tratados'!J35) -> 1924313.8 | Z30: =IF('Dados tratados'!J30="","",'Dados tratados'!J30) -> 38.949208 | AA30: =IF('Dados tratados'!J33="","",'Dados tratados'!J33) -> -5.4411455 | AB30: =IF('Dados tratados'!J31="","",'Dados tratados'!J31) -> 85.2 | AC30: =IF('Dados tratados'!J29="","",'Dados tratados'!J29) -> -2.6 | AD30: =IF('Dados tratados'!J28="","",'Dados tratados'!J28) -> 524.431 | AE30: =IF('Dados tratados'!J27="","",'Dados tratados'!J27) -> 34.3 | AF30: =IF('Dados tratados'!D37="","",'Dados tratados'!D37) | AG30: =IF('Dados tratados'!D36="","",'Dados tratados'!D36)
A31: Argentina | B31: 2019 | C31: =IF('Dados tratados'!E46="","",'Dados tratados'!E46) -> 44939000 | V31: =IF('Dados tratados'!E38="","",'Dados tratados'!E38) -> 5.4735379e+12 | W31: =IF('Dados tratados'!G38="","",'Dados tratados'!G38) -> 210771147006548 | X31: =IF('Dados tratados'!I38="","",'Dados tratados'!I38) -> 4690161 | Y31: =IF('Dados tratados'!J47="","",'Dados tratados'!J47) -> 2754645.6 | Z31: =IF('Dados tratados'!J42="","",'Dados tratados'!J42) -> 38.129058 | AA31: =IF('Dados tratados'!J45="","",'Dados tratados'!J45) -> -4.4447575 | AB31: =IF('Dados tratados'!J43="","",'Dados tratados'!J43) -> 89.8 | AC31: =IF('Dados tratados'!J41="","",'Dados tratados'!J41) -> -2 | AD31: =IF('Dados tratados'!J40="","",'Dados tratados'!J40) -> 446.762 | AE31: =IF('Dados tratados'!J39="","",'Dados tratados'!J39) -> 53.5 | AF31: =IF('Dados tratados'!D49="","",'Dados tratados'!D49) | AG31: =IF('Dados tratados'!D48="","",'Dados tratados'!D48)
A32: Argentina | B32: 2020 | C32: =IF('Dados tratados'!E58="","",'Dados tratados'!E58) -> 45377000 | V32: =IF('Dados tratados'!E50="","",'Dados tratados'!E50) -> 7.2374102e+12 | W32: =IF('Dados tratados'!G50="","",'Dados tratados'!G50) -> 1.9626275e+14 | X32: =IF('Dados tratados'!I50="","",'Dados tratados'!I50) -> 4325159.2 | Y32: =IF('Dados tratados'!J59="","",'Dados tratados'!J59) -> 3742115.7 | Z32: =IF('Dados tratados'!J54="","",'Dados tratados'!J54) -> 42.47924 | AA32: =IF('Dados tratados'!J57="","",'Dados tratados'!J57) -> -8.6740712 | AB32: =IF('Dados tratados'!J55="","",'Dados tratados'!J55) -> 103.8 | AC32: =IF('Dados tratados'!J53="","",'Dados tratados'!J53) -> -9.9 | AD32: =IF('Dados tratados'!J52="","",'Dados tratados'!J52) -> 385.218 | AE32: =IF('Dados tratados'!J51="","",'Dados tratados'!J51) -> 42 | AF32: =IF('Dados tratados'!D61="","",'Dados tratados'!D61) | AG32: =IF('Dados tratados'!D60="","",'Dados tratados'!D60)
A33: Argentina | B33: 2021 | C33: =IF('Dados tratados'!E70="","",'Dados tratados'!E70) -> 45809000 | V33: =IF('Dados tratados'!E62="","",'Dados tratados'!E62) -> 11906730771054 | W33: =IF('Dados tratados'!G62="","",'Dados tratados'!G62) -> 2.1757717e+14 | X33: =IF('Dados tratados'!I62="","",'Dados tratados'!I62) -> 4749659.8 | Y33: =IF('Dados tratados'!J71="","",'Dados tratados'!J71) -> 6116121.7 | Z33: =IF('Dados tratados'!J66="","",'Dados tratados'!J66) -> 37.883365 | AA33: =IF('Dados tratados'!J69="","",'Dados tratados'!J69) -> -4.332952 | AB33: =IF('Dados tratados'!J67="","",'Dados tratados'!J67) -> 81 | AC33: =IF('Dados tratados'!J65="","",'Dados tratados'!J65) -> 10.4 | AD33: =IF('Dados tratados'!J64="","",'Dados tratados'!J64) -> 486.04 | AE33: =IF('Dados tratados'!J63="","",'Dados tratados'!J63) -> 48.4 | AF33: =IF('Dados tratados'!D73="","",'Dados tratados'!D73) | AG33: =IF('Dados tratados'!D72="","",'Dados tratados'!D72)
A34: Argentina | B34: 2022 | C34: =IF('Dados tratados'!E82="","",'Dados tratados'!E82) -> 46235000 | V34: =IF('Dados tratados'!E74="","",'Dados tratados'!E74) -> 2.1540626e+13 | W34: =IF('Dados tratados'!G74="","",'Dados tratados'!G74) -> 2.2831889e+14 | X34: =IF('Dados tratados'!I74="","",'Dados tratados'!I74) -> 4938226.3 | Y34: =IF('Dados tratados'!J83="","",'Dados tratados'!J83) -> 11276057 | Z34: =IF('Dados tratados'!J78="","",'Dados tratados'!J78) -> 37.643123 | AA34: =IF('Dados tratados'!J81="","",'Dados tratados'!J81) -> -3.8363851 | AB34: =IF('Dados tratados'!J79="","",'Dados tratados'!J79) -> 84.3 | AC34: =IF('Dados tratados'!J77="","",'Dados tratados'!J77) -> 6 | AD34: =IF('Dados tratados'!J76="","",'Dados tratados'!J76) -> 633.52 | AE34: =IF('Dados tratados'!J75="","",'Dados tratados'!J75) -> 72.4 | AF34: =IF('Dados tratados'!D85="","",'Dados tratados'!D85) | AG34: =IF('Dados tratados'!D84="","",'Dados tratados'!D84)
A35: Argentina | B35: 2023 | C35: =IF('Dados tratados'!E94="","",'Dados tratados'!E94) -> 46655000 | V35: =IF('Dados tratados'!E86="","",'Dados tratados'!E86) -> 4.6463191e+13 | W35: =IF('Dados tratados'!G86="","",'Dados tratados'!G86) -> 2.1091413e+14 | X35: =IF('Dados tratados'!I86="","",'Dados tratados'!I86) -> 4520718.6 | Y35: =IF('Dados tratados'!J95="","",'Dados tratados'!J95) -> 25030205 | Z35: =IF('Dados tratados'!J90="","",'Dados tratados'!J90) -> 37.637348 | AA35: =IF('Dados tratados'!J93="","",'Dados tratados'!J93) -> -5.2809834 | AB35: =IF('Dados tratados'!J91="","",'Dados tratados'!J91) -> 153.4 | AC35: =IF('Dados tratados'!J89="","",'Dados tratados'!J89) -> -1.9 | AD35: =IF('Dados tratados'!J88="","",'Dados tratados'!J88) -> 654.081 | AE35: =IF('Dados tratados'!J87="","",'Dados tratados'!J87) -> 133.5 | AF35: =IF('Dados tratados'!D97="","",'Dados tratados'!D97) | AG35: =IF('Dados tratados'!D96="","",'Dados tratados'!D96)
A36: Argentina | B36: 2024 | C36: =IF('Dados tratados'!E106="","",'Dados tratados'!E106) -> 47068000 | V36: =IF('Dados tratados'!E98="","",'Dados tratados'!E98) -> 142031453049165 | W36: =IF('Dados tratados'!G98="","",'Dados tratados'!G98) -> 2.0154263e+14 | X36: =IF('Dados tratados'!I98="","",'Dados tratados'!I98) -> 4281945.9 | Y36: =IF('Dados tratados'!J107="","",'Dados tratados'!J107) -> 73874240 | Z36: =IF('Dados tratados'!J102="","",'Dados tratados'!J102) -> 31.019182 | AA36: =IF('Dados tratados'!J105="","",'Dados tratados'!J105) -> 0.45837829 | AB36: =IF('Dados tratados'!J103="","",'Dados tratados'!J103) -> 84.6 | AC36: =IF('Dados tratados'!J101="","",'Dados tratados'!J101) -> -1.4 | AD36: =IF('Dados tratados'!J100="","",'Dados tratados'!J100) -> 637.744 | AE36: =IF('Dados tratados'!J99="","",'Dados tratados'!J99) -> 219.9 | AF36: =IF('Dados tratados'!D109="","",'Dados tratados'!D109) | AG36: =IF('Dados tratados'!D108="","",'Dados tratados'!D108)
A37: Argentina | B37: 2025 | C37: =IF('Dados tratados'!E118="","",'Dados tratados'!E118) -> 47474000 | V37: =IF('Dados tratados'!E110="","",'Dados tratados'!E110) -> 200448446615565 | W37: =IF('Dados tratados'!G110="","",'Dados tratados'!G110) -> 200448446615565 | X37: =IF('Dados tratados'!I110="","",'Dados tratados'!I110) -> 4222278.4 | Y37: =IF('Dados tratados'!J119="","",'Dados tratados'!J119) -> 1.0397413e+08 | Z37: =IF('Dados tratados'!J114="","",'Dados tratados'!J114) | AA37: =IF('Dados tratados'!J117="","",'Dados tratados'!J117) -> -0.15602149 | AB37: =IF('Dados tratados'!J115="","",'Dados tratados'!J115) -> 80.1 | AC37: =IF('Dados tratados'!J113="","",'Dados tratados'!J113) -> 4.5 | AD37: =IF('Dados tratados'!J112="","",'Dados tratados'!J112) -> 683.589 | AE37: =IF('Dados tratados'!J111="","",'Dados tratados'!J111) -> 41.9 | AF37: =IF('Dados tratados'!D121="","",'Dados tratados'!D121) -> 11769219 | AG37: =IF('Dados tratados'!D120="","",'Dados tratados'!D120) -> 1453819

Sheet Dados brutos atualizados
A1: Entidade | B1: Ano | C1: Período/competência | D1: Variável | E1: Valor na fonte | F1: Unidade publicada | G1: Fator para unidade padrão | H1: Campo/linha de origem | I1: Código/variável-fonte | J1: Status de observação | K1: Observação/metadado | L1: URL da fonte
A2: Argentina | B2: 2016 | C2: 2016 | D2: Arrecadação federal total ARCA (TOTAL GENERAL) | E2: 2.2730474e+09 | F2: mil pesos argentinos (ARS) | G2: 1000 | H2: linha 8; coluna TOTAL; cabeçalho: Miles de pesos | I2: Serie anual 2016 | J2: Publicado | K2: Total de tributos, recursos da seguridade social e aduanas; não é receita total de todo o governo. | L2: https://contenidos.afip.gob.ar/institucional/estudios/archivos/serie2016.xls
A3: Argentina | B3: 2016 | C3: 2016 | D3: CPI inflation annual average (%) | F3: Annual percent change | G3: 1 | H3: PCPIPCH | I3: World Economic Outlook (October 2026) | J3: Sem dado no endpoint/vintage; mantido ausente | K3: Indicador PCPIPCH; fonte IMF: World Economic Outlook (October 2026); metadado do endpoint preservado. | L3: https://www.imf.org/external/datamapper/api/v2/PCPIPCH/ARG?periods=2016,2017,2018,2019,2020,2021,2022,2023,2024,2025
A4: Argentina | B4: 2016 | C4: 2016 | D4: GDP nominal current (USD billion) | E4: 556.774 | F4: Billions of U.S. dollars | G4: 1 | H4: NGDPD | I4: World Economic Outlook (October 2026) | J4: WEO October 2026; latest history/vintage, subject to revision | K4: Indicador NGDPD; fonte IMF: World Economic Outlook (October 2026); metadado do endpoint preservado. | L4: https://www.imf.org/external/datamapper/api/v2/NGDPD/ARG?periods=2016,2017,2018,2019,2020,2021,2022,2023,2024,2025
A5: Argentina | B5: 2016 | C5: 2016 | D5: GDP real growth (%) | E5: -2.1 | F5: Annual percent change | G5: 1 | H5: NGDP_RPCH | I5: World Economic Outlook (October 2026) | J5: WEO October 2026; latest history/vintage, subject to revision | K5: Indicador NGDP_RPCH; fonte IMF: World Economic Outlook (October 2026); metadado do endpoint preservado. | L5: https://www.imf.org/external/datamapper/api/v2/NGDP_RPCH/ARG?periods=2016,2017,2018,2019,2020,2021,2022,2023,2024,2025
A6: Argentina | B6: 2016 | C6: 2016 | D6: Government expenditure (% GDP, FPP) | E6: 41.522021 | F6: % of GDP | G6: 1 | H6: exp | I6: Public Finances in Modern History Database (Dec 2025) | J6: FPP Dec 2025; 2025 not published in this series | K6: Indicador exp; fonte IMF: Public Finances in Modern History Database (Dec 2025); metadado do endpoint preservado. | L6: https://www.imf.org/external/datamapper/api/v2/exp/ARG?periods=2016,2017,2018,2019,2020,2021,2022,2023,2024,2025
A7: Argentina | B7: 2016 | C7: 2016 | D7: Gross debt (% GDP) | E7: 53.1 | F7: Percent of GDP | G7: 1 | H7: GGXWDG_NGDP | I7: World Economic Outlook (October 2026) | J7: WEO October 2026; latest history/vintage, subject to revision | K7: Indicador GGXWDG_NGDP; fonte IMF: World Economic Outlook (October 2026); metadado do endpoint preservado. | L7: https://www.imf.org/external/datamapper/api/v2/GGXWDG_NGDP/ARG?periods=2016,2017,2018,2019,2020,2021,2022,2023,2024,2025
A8: Argentina | B8: 2016 | C8: 2016 | D8: Juros líquidos intra-SPN, base caja (2025) | F8: millones de pesos argentinos (ARS) | G8: 1000000 | H8: nota oficial; fechamento anual 2025 | I8: Hacienda/SPN Base Caja | J8: Publicado somente para 2025; anos anteriores não preenchidos nesta observação de fonte | K8: Resultado primário e financeiro do SPN base caixa; perímetro distinto das contas de governo geral IMF. | L8: https://www.argentina.gob.ar/noticias/en-el-ano-2025-el-sector-publico-nacional-registro-un-superavit-financiero-de-1453819
A9: Argentina | B9: 2016 | C9: 2016 | D9: Net lending/borrowing (% GDP) | E9: -6.654669 | F9: % of GDP | G9: 1 | H9: GGXCNL_G01_GDP_PT | I9: Fiscal Monitor (October 2026) | J9: WEO October 2026; latest history/vintage, subject to revision | K9: Indicador GGXCNL_G01_GDP_PT; fonte IMF: Fiscal Monitor (October 2026); metadado do endpoint preservado. | L9: https://www.imf.org/external/datamapper/api/v2/GGXCNL_G01_GDP_PT/ARG?periods=2016,2017,2018,2019,2020,2021,2022,2023,2024,2025
A10: Argentina | B10: 2016 | C10: 2016 | D10: Population (IMF WEO) | E10: 43.59 | F10: millions of persons | G10: 1000000 | H10: LP | I10: World Economic Outlook (October 2026) | J10: WEO October 2026; latest history/vintage, subject to revision | K10: Indicador LP; fonte IMF: World Economic Outlook (October 2026); metadado do endpoint preservado. | L10: https://www.imf.org/external/datamapper/api/v2/LP/ARG?periods=2016,2017,2018,2019,2020,2021,2022,2023,2024,2025
A11: Argentina | B11: 2016 | C11: 2016 | D11: RON transferências a províncias/CABA (monto publicado) | E11: 1120751.4 | F11: monto conforme CSV; unidade/escala não declarada | H11: soma de monto por ano (27 jurisdições), agregando imposto e regime | I11: ano/provincia/impuesto/regimen/monto | J11: Publicado em unidade reportada; não convertida | K11: RON inclui coparticipação e outros regimes distribuídos; o arquivo não declara unidade monetária. Valores nominais não foram deflacionados nem usados em comparações de nível. | L11: https://www.argentina.gob.ar/sites/default/files/serie_ron_2003_2025.csv
A12: Argentina | B12: 2016 | C12: 2016 | D12: Resultado financeiro SPN, base caja (2025) | F12: millones de pesos argentinos (ARS) | G12: 1000000 | H12: nota oficial; fechamento anual 2025 | I12: Hacienda/SPN Base Caja | J12: Publicado somente para 2025; anos anteriores não preenchidos nesta observação de fonte | K12: Resultado primário e financeiro do SPN base caixa; perímetro distinto das contas de governo geral IMF. | L12: https://www.argentina.gob.ar/noticias/en-el-ano-2025-el-sector-publico-nacional-registro-un-superavit-financiero-de-1453819
A13: Argentina | B13: 2016 | C13: 2016 | D13: Resultado primário SPN, base caja (2025) | F13: millones de pesos argentinos (ARS) | G13: 1000000 | H13: nota oficial; fechamento anual 2025 | I13: Hacienda/SPN Base Caja | J13: Publicado somente para 2025; anos anteriores não preenchidos nesta observação de fonte | K13: Resultado primário e financeiro do SPN base caixa; perímetro distinto das contas de governo geral IMF. | L13: https://www.argentina.gob.ar/noticias/en-el-ano-2025-el-sector-publico-nacional-registro-un-superavit-financiero-de-1453819
A14: Argentina | B14: 2017 | C14: 2017 | D14: Arrecadação federal total ARCA (TOTAL GENERAL) | E14: 2.8422167e+09 | F14: mil pesos argentinos (ARS) | G14: 1000 | H14: linha 8; coluna TOTAL; cabeçalho: Miles de pesos | I14: Serie anual 2017 | J14: Publicado | K14: Total de tributos, recursos da seguridade social e aduanas; não é receita total de todo o governo. | L14: https://contenidos.afip.gob.ar/institucional/estudios/archivos/serie2017.xls
A15: Argentina | B15: 2017 | C15: 2017 | D15: CPI inflation annual average (%) | E15: 25.7 | F15: Annual percent change | G15: 1 | H15: PCPIPCH | I15: World Economic Outlook (October 2026) | J15: WEO October 2026; latest history/vintage, subject to revision | K15: Indicador PCPIPCH; fonte IMF: World Economic Outlook (October 2026); metadado do endpoint preservado. | L15: https://www.imf.org/external/datamapper/api/v2/PCPIPCH/ARG?periods=2016,2017,2018,2019,2020,2021,2022,2023,2024,2025
A16: Argentina | B16: 2017 | C16: 2017 | D16: GDP nominal current (USD billion) | E16: 643.861 | F16: Billions of U.S. dollars | G16: 1 | H16: NGDPD | I16: World Economic Outlook (October 2026) | J16: WEO October 2026; latest history/vintage, subject to revision | K16: Indicador NGDPD; fonte IMF: World Economic Outlook (October 2026); metadado do endpoint preservado. | L16: https://www.imf.org/external/datamapper/api/v2/NGDPD/ARG?periods=2016,2017,2018,2019,2020,2021,2022,2023,2024,2025
A17: Argentina | B17: 2017 | C17: 2017 | D17: GDP real growth (%) | E17: 2.8 | F17: Annual percent change | G17: 1 | H17: NGDP_RPCH | I17: World Economic Outlook (October 2026) | J17: WEO October 2026; latest history/vintage, subject to revision | K17: Indicador NGDP_RPCH; fonte IMF: World Economic Outlook (October 2026); metadado do endpoint preservado. | L17: https://www.imf.org/external/datamapper/api/v2/NGDP_RPCH/ARG?periods=2016,2017,2018,2019,2020,2021,2022,2023,2024,2025
A18: Argentina | B18: 2017 | C18: 2017 | D18: Government expenditure (% GDP, FPP) | E18: 41.121454 | F18: % of GDP | G18: 1 | H18: exp | I18: Public Finances in Modern History Database (Dec 2025) | J18: FPP Dec 2025; 2025 not published in this series | K18: Indicador exp; fonte IMF: Public Finances in Modern History Database (Dec 2025); metadado do endpoint preservado. | L18: https://www.imf.org/external/datamapper/api/v2/exp/ARG?periods=2016,2017,2018,2019,2020,2021,2022,2023,2024,2025
A19: Argentina | B19: 2017 | C19: 2017 | D19: Gross debt (% GDP) | E19: 57 | F19: Percent of GDP | G19: 1 | H19: GGXWDG_NGDP | I19: World Economic Outlook (October 2026) | J19: WEO October 2026; latest history/vintage, subject to revision | K19: Indicador GGXWDG_NGDP; fonte IMF: World Economic Outlook (October 2026); metadado do endpoint preservado. | L19: https://www.imf.org/external/datamapper/api/v2/GGXWDG_NGDP/ARG?periods=2016,2017,2018,2019,2020,2021,2022,2023,2024,2025
A20: Argentina | B20: 2017 | C20: 2017 | D20: Juros líquidos intra-SPN, base caja (2025) | F20: millones de pesos argentinos (ARS) | G20: 1000000 | H20: nota oficial; fechamento anual 2025 | I20: Hacienda/SPN Base Caja | J20: Publicado somente para 2025; anos anteriores não preenchidos nesta observação de fonte | K20: Resultado primário e financeiro do SPN base caixa; perímetro distinto das contas de governo geral IMF. | L20: https://www.argentina.gob.ar/noticias/en-el-ano-2025-el-sector-publico-nacional-registro-un-superavit-financiero-de-1453819
A21: Argentina | B21: 2017 | C21: 2017 | D21: Net lending/borrowing (% GDP) | E21: -6.6933411 | F21: % of GDP | G21: 1 | H21: GGXCNL_G01_GDP_PT | I21: Fiscal Monitor (October 2026) | J21: WEO October 2026; latest history/vintage, subject to revision | K21: Indicador GGXCNL_G01_GDP_PT; fonte IMF: Fiscal Monitor (October 2026); metadado do endpoint preservado. | L21: https://www.imf.org/external/datamapper/api/v2/GGXCNL_G01_GDP_PT/ARG?periods=2016,2017,2018,2019,2020,2021,2022,2023,2024,2025
A22: Argentina | B22: 2017 | C22: 2017 | D22: Population (IMF WEO) | E22: 44.045 | F22: millions of persons | G22: 1000000 | H22: LP | I22: World Economic Outlook (October 2026) | J22: WEO October 2026; latest history/vintage, subject to revision | K22: Indicador LP; fonte IMF: World Economic Outlook (October 2026); metadado do endpoint preservado. | L22: https://www.imf.org/external/datamapper/api/v2/LP/ARG?periods=2016,2017,2018,2019,2020,2021,2022,2023,2024,2025
A23: Argentina | B23: 2017 | C23: 2017 | D23: RON transferências a províncias/CABA (monto publicado) | E23: 1457199.8 | F23: monto conforme CSV; unidade/escala não declarada | H23: soma de monto por ano (27 jurisdições), agregando imposto e regime | I23: ano/provincia/impuesto/regimen/monto | J23: Publicado em unidade reportada; não convertida | K23: RON inclui coparticipação e outros regimes distribuídos; o arquivo não declara unidade monetária. Valores nominais não foram deflacionados nem usados em comparações de nível. | L23: https://www.argentina.gob.ar/sites/default/files/serie_ron_2003_2025.csv
A24: Argentina | B24: 2017 | C24: 2017 | D24: Resultado financeiro SPN, base caja (2025) | F24: millones de pesos argentinos (ARS) | G24: 1000000 | H24: nota oficial; fechamento anual 2025 | I24: Hacienda/SPN Base Caja | J24: Publicado somente para 2025; anos anteriores não preenchidos nesta observação de fonte | K24: Resultado primário e financeiro do SPN base caixa; perímetro distinto das contas de governo geral IMF. | L24: https://www.argentina.gob.ar/noticias/en-el-ano-2025-el-sector-publico-nacional-registro-un-superavit-financiero-de-1453819
A25: Argentina | B25: 2017 | C25: 2017 | D25: Resultado primário SPN, base caja (2025) | F25: millones de pesos argentinos (ARS) | G25: 1000000 | H25: nota oficial; fechamento anual 2025 | I25: Hacienda/SPN Base Caja | J25: Publicado somente para 2025; anos anteriores não preenchidos nesta observação de fonte | K25: Resultado primário e financeiro do SPN base caixa; perímetro distinto das contas de governo geral IMF. | L25: https://www.argentina.gob.ar/noticias/en-el-ano-2025-el-sector-publico-nacional-registro-un-superavit-financiero-de-1453819
A26: Argentina | B26: 2018 | C26: 2018 | D26: Arrecadação federal total ARCA (TOTAL GENERAL) | E26: 3.7134091e+09 | F26: mil pesos argentinos (ARS) | G26: 1000 | H26: linha 8; coluna TOTAL; cabeçalho: Miles de pesos | I26: Serie anual 2018 | J26: Publicado | K26: Total de tributos, recursos da seguridade social e aduanas; não é receita total de todo o governo. | L26: https://contenidos.afip.gob.ar/institucional/estudios/archivos/serie2018.xls
A27: Argentina | B27: 2018 | C27: 2018 | D27: CPI inflation annual average (%) | E27: 34.3 | F27: Annual percent change | G27: 1 | H27: PCPIPCH | I27: World Economic Outlook (October 2026) | J27: WEO October 2026; latest history/vintage, subject to revision | K27: Indicador PCPIPCH; fonte IMF: World Economic Outlook (October 2026); metadado do endpoint preservado. | L27: https://www.imf.org/external/datamapper/api/v2/PCPIPCH/ARG?periods=2016,2017,2018,2019,2020,2021,2022,2023,2024,2025
A28: Argentina | B28: 2018 | C28: 2018 | D28: GDP nominal current (USD billion) | E28: 524.431 | F28: Billions of U.S. dollars | G28: 1 | H28: NGDPD | I28: World Economic Outlook (October 2026) | J28: WEO October 2026; latest history/vintage, subject to revision | K28: Indicador NGDPD; fonte IMF: World Economic Outlook (October 2026); metadado do endpoint preservado. | L28: https://www.imf.org/external/datamapper/api/v2/NGDPD/ARG?periods=2016,2017,2018,2019,2020,2021,2022,2023,2024,2025
A29: Argentina | B29: 2018 | C29: 2018 | D29: GDP real growth (%) | E29: -2.6 | F29: Annual percent change | G29: 1 | H29: NGDP_RPCH | I29: World Economic Outlook (October 2026) | J29: WEO October 2026; latest history/vintage, subject to revision | K29: Indicador NGDP_RPCH; fonte IMF: World Economic Outlook (October 2026); metadado do endpoint preservado. | L29: https://www.imf.org/external/datamapper/api/v2/NGDP_RPCH/ARG?periods=2016,2017,2018,2019,2020,2021,2022,2023,2024,2025
A30: Argentina | B30: 2018 | C30: 2018 | D30: Government expenditure (% GDP, FPP) | E30: 38.949208 | F30: % of GDP | G30: 1 | H30: exp | I30: Public Finances in Modern History Database (Dec 2025) | J30: FPP Dec 2025; 2025 not published in this series | K30: Indicador exp; fonte IMF: Public Finances in Modern History Database (Dec 2025); metadado do endpoint preservado. | L30: https://www.imf.org/external/datamapper/api/v2/exp/ARG?periods=2016,2017,2018,2019,2020,2021,2022,2023,2024,2025
